<?xml version="1.0"?>
<sdf version="1.7">
  <model name="box_to_push">
    <!-- Ghost body of negligible mass. -->
    <link name="ghost_body_x">
      <inertial>
        <mass>1.0e-6</mass>
        <inertia>
          <ixx>1.0e-6</ixx>
          <ixy>0</ixy>
          <ixz>0</ixz>
          <iyy>1.0e-6</iyy>
          <iyz>0</iyz>
          <izz>1.0e-6</izz>
        </inertia>
      </inertial>
    </link>

    <link name="ghost_body_y">
      <inertial>
        <mass>1.0e-6</mass>
        <inertia>
          <ixx>1.0e-6</ixx>
          <ixy>0</ixy>
          <ixz>0</ixz>
          <iyy>1.0e-6</iyy>
          <iyz>0</iyz>
          <izz>1.0e-6</izz>
        </inertia>
      </inertial>
    </link>

    <joint name="x_slider" type="prismatic">
      <parent>world</parent>
      <child>ghost_body_x</child>
      <axis>
        <xyz>1 0 0</xyz>
        <!-- Drake attaches an actuator to all joints with a non-zero effort
             limit. We do not want an actuator for this joint. -->
        <limit>
          <effort>0</effort>
        </limit>
      </axis>
    </joint>

    <joint name="z_slider" type="prismatic">
      <parent>ghost_body_x</parent>
      <child>ghost_body_y</child>
      <axis>
        <xyz>0 1 0</xyz>
        <!-- Drake attaches an actuator to all joints with a non-zero effort
             limit. We do not want an actuator for this joint and therefore we
             set a zero effort limit. -->
        <limit>
          <effort>0</effort>
        </limit>
      </axis>
    </joint>

    <joint name="rotation" type="revolute">
      <parent>ghost_body_y</parent>
      <child>box</child>
      <axis>
        <xyz>0 0 1</xyz>
        <!-- Drake attaches an actuator to all joints with a non-zero effort
             limit. We do not want an actuator for this joint and therefore we
             set a zero effort limit. -->
        <limit>
          <effort>0</effort>
        </limit>
      </axis>
    </joint>

    <link name="box">
      <inertial>
        <mass>0.1</mass>
        <inertia>
          <ixx>0.002</ixx>
          <ixy>0</ixy>
          <ixz>0</ixz>
          <iyy>0.002</iyy>
          <iyz>0</iyz>
          <izz>0.002</izz>
        </inertia>
      </inertial>

      <visual name="box_visual">
        <geometry>
          <box>
            <size>0.276 0.198 0.176</size>
          </box>
        </geometry>
        <material>
          <diffuse>0.9 0.9 0.9 0.9</diffuse>
        </material>
      </visual>

      <collision name="collision">
        <geometry>
          <box>
            <size>0.276 0.198 0.176</size>
          </box>
        </geometry>
        <surface>
          <friction>
            <ode>
              <mu>0.5</mu>
              <mu2>0.5</mu2>
            </ode>
          </friction>
        </surface>
      </collision>


    </link>
  </model>
</sdf>