<?xml version="1.0"?>
<sdf version="1.7">
  <!-- Note:
       This file defines the model for a box with two degrees of freedom
       (DOFs): a) one DOF for the horizontal motion along the y axis and
       b) one DOF for the vertical motion along the z axis.
       To this end, this model defines a small "ghost body" between
       the box and the world so that we can attach two prismatic joints for
       these two DOFs. The ghost body has negligible mass.
  -->
  <model name="sphere_y">
    <!-- The y slider will have an actuator with a corresponding input port
         in our MultibodyPlant model so that we can apply an external force.
    -->
    <joint name="y_slider" type="prismatic">
      <parent>world</parent>
      <child>box</child>
      <axis>
        <xyz>0 1 0</xyz>
        <!-- Drake attaches an actuator to all joints with a non-zero effort
             limit. We do not want an actuator for this joint. -->
        <limit>
          <effort>0</effort>
        </limit>
        <dynamics>
          <damping>50</damping>
        </dynamics>
      </axis>
    </joint>
    <!-- The model for a solid sphere of uniform density. -->
    <link name="box">
      <pose>0 0 -0.6 0 0 0</pose>
      <inertial>
        <mass>1.0</mass>
        <inertia>
          <ixx>0.004</ixx>
          <ixy>0</ixy>
          <ixz>0</ixz>
          <iyy>0.004</iyy>
          <iyz>0</iyz>
          <izz>0.004</izz>
        </inertia>
      </inertial>
      <visual name="visual">
        <geometry>
          <box>
            <size>1.0 1.0 1.0</size>
          </box>
        </geometry>
        <material>
          <diffuse>0.8 0.8 0.8 1.0</diffuse>
        </material>
      </visual>
      <collision name="collision">
        <geometry>
          <box>
            <size>1.0 1.0 1.0</size>
          </box>
        </geometry>
        <surface>
          <friction>
            <ode>
              <!-- MultibodyPlant's time stepping only uses the static
                   coefficient of friction, <mu>. -->
              <mu>1.0</mu>
              <mu2>1.0</mu2>
            </ode>
          </friction>
        </surface>
      </collision>
    </link>
  </model>
</sdf>