<?xml version="1.0"?>
<sdf version="1.7">

  <!-- Note:
       This file defines the model for a box with two degrees of freedom
       (DOFs): a) one DOF for the horizontal motion along the y axis and
       b) one DOF for the vertical motion along the z axis.
       To this end, this model defines a small "ghost body" between
       the box and the world so that we can attach two prismatic joints for
       these two DOFs. The ghost body has negligible mass.
  -->
  <!-- world->ghost_body_y->ghost_body_z_sphere-->
  <model name="door">
    <!-- The model for a solid box of uniform density. -->

    <joint name="z_rotation" type="revolute">
      <parent>world</parent>
      <child>door</child>
      <axis>
        <xyz>0 0 1</xyz>
        <!-- Drake attaches an actuator to all joints with a non-zero effort
             limit. We do not want an actuator for this joint. -->
        <limit>
          <effort>0</effort>
        </limit>
      </axis>
    </joint>

    <link name="door">
      <pose>0 -0.5 0 0 0 0</pose>
      <inertial>
        <mass>0.1</mass>
        <inertia>
          <ixx>0.010334166666666667</ixx>
          <ixy>0</ixy>
          <ixz>0</ixz>
          <iyy>0.008354166666666666</iyy>
          <iyz>0</iyz>
          <izz>0.0020216666666666664</izz>
        </inertia>
      </inertial>

      <visual name="box_visual">
        <pose>0 0.25 0 0 0 0 </pose>
        <geometry>
          <box>
            <size>0.05 0.49 1.0</size>
          </box>
        </geometry>
        <material>
          <diffuse>0.1 0.5 0.5 0.8</diffuse>
        </material>
      </visual>

      <collision name="collision">
        <pose>0 0.25 0 0 0 0 </pose>
        <geometry>
          <box>
            <size>0.05 0.49 1.0</size>
          </box>
        </geometry>
        <surface>
          <friction>
            <ode>
              <mu>0.5</mu>
              <mu2>0.5</mu2>
            </ode>
          </friction>
        </surface>
      </collision>
    </link>

    <joint name="x_rotation" type="revolute">
      <parent>door</parent>
      <child>sphere</child>
      <axis>
        <xyz>1 0 0</xyz>
        <!-- Drake attaches an actuator to all joints with a non-zero effort
             limit. We do not want an actuator for this joint. -->
        <limit>
          <effort>0</effort>
        </limit>
      </axis>
    </joint>

    <link name="sphere">
      <pose>-0.075 -0.075 0 0 0 0</pose>
      <inertial>
        <mass>0.3</mass>
        <inertia>
          <ixx>0.001</ixx>
          <ixy>0</ixy>
          <ixz>0</ixz>
          <iyy>0.001</iyy>
          <iyz>0</iyz>
          <izz>0.001</izz>
        </inertia>
      </inertial>

      <visual name="visual">
        <geometry>
          <sphere>
            <radius>0.05</radius>
          </sphere>
        </geometry>
        <material>
          <diffuse>0.6 0.2 0.2 0.9</diffuse>
        </material>
      </visual>

      <visual name="visual_cylinder">
        <pose>0.075 0 0 0 1.57079632 0 </pose>
        <geometry>
          <cylinder>
            <radius>0.025</radius>
            <length>0.1</length>
          </cylinder>
        </geometry>
        <material>
          <diffuse>0.6 0.2 0.2 0.9</diffuse>
        </material>
      </visual>

      <visual name="visual_hinge">
        <pose>0 0 0 0 0 0 </pose>
        <geometry>
          <sphere>
            <radius>0.025</radius>
          </sphere>
        </geometry>
        <material>
          <diffuse>0.6 0.2 0.2 0.9</diffuse>
        </material>
      </visual>

      <visual name="visual_hinge1">
        <pose>0 0.05 0 0 0 0 </pose>
        <geometry>
          <sphere>
            <radius>0.025</radius>
          </sphere>
        </geometry>
        <material>
          <diffuse>0.6 0.2 0.2 0.9</diffuse>
        </material>
      </visual>

      <visual name="visual_hinge2">
        <pose>0 0.1 0 0 0 0 </pose>
        <geometry>
          <sphere>
            <radius>0.025</radius>
          </sphere>
        </geometry>
        <material>
          <diffuse>0.6 0.2 0.2 0.9</diffuse>
        </material>
      </visual>

      <visual name="visual_hinge_cylinder">
        <pose>0 0.05 0 1.57079632 0 0 </pose>
        <geometry>
          <cylinder>
            <radius>0.025</radius>
            <length>0.1</length>
          </cylinder>
        </geometry>
        <material>
          <diffuse>0.6 0.2 0.2 0.9</diffuse>
        </material>
      </visual>


      <collision name="collision">
        <geometry>
          <sphere>
            <radius>0.05</radius>
          </sphere>
        </geometry>
        <surface>
          <friction>
            <ode>
              <mu>1.0</mu>
              <mu2>1.0</mu2>
            </ode>
          </friction>
        </surface>
      </collision>

      <collision name="collision_hinge1">
        <pose>0.0 0 0 0 0 0 </pose>
        <geometry>
          <sphere>
            <radius>0.025</radius>
          </sphere>
        </geometry>
        <surface>
          <friction>
            <ode>
              <mu>1.0</mu>
              <mu2>1.0</mu2>
            </ode>
          </friction>
        </surface>
      </collision>

      <collision name="collision_hinge2">
        <pose>0.0 0.05 0 0 0 0 </pose>
        <geometry>
          <sphere>
            <radius>0.025</radius>
          </sphere>
        </geometry>
        <surface>
          <friction>
            <ode>
              <mu>1.0</mu>
              <mu2>1.0</mu2>
            </ode>
          </friction>
        </surface>
      </collision>

      <collision name="collision_hinge3">
        <pose>0.0 0.1 0 0 0 0 </pose>
        <geometry>
          <sphere>
            <radius>0.025</radius>
          </sphere>
        </geometry>
        <surface>
          <friction>
            <ode>
              <mu>1.0</mu>
              <mu2>1.0</mu2>
            </ode>
          </friction>
        </surface>
      </collision>


    </link>

  </model>
</sdf>
