<?xml version="1.0"?>
<sdf version="1.7">
  <model name="gripper">
    <link name="gripper_body">
      <pose>0 0 0 0 0 0</pose>
      <inertial>
        <mass>1</mass>
        <inertia>
          <ixx>0.1</ixx>
          <ixy>0</ixy>
          <ixz>0</ixz>
          <iyy>0.1</iyy>
          <iyz>0</iyz>
          <izz>0.1</izz>
        </inertia>
      </inertial>
    </link>

    <joint name="y_slider_left" type="prismatic">
      <parent>gripper_body</parent>
      <child>left_finger</child>
      <axis>
        <xyz>0 1 0</xyz>
      </axis>
    </joint>

    <joint name="y_slider_right" type="prismatic">
      <parent>gripper_body</parent>
      <child>right_finger</child>
      <axis>
        <xyz>0 1 0</xyz>
      </axis>
    </joint>

    <joint name="z_slider" type="prismatic">
      <parent>world</parent>
      <child>gripper_body</child>
      <axis>
        <xyz>0 0 1</xyz>
      </axis>
    </joint>

    <!-- The model for a solid box of uniform density. -->
    <link name="left_finger">
      <pose>0 -0.01 0 0 0 0</pose>
      <inertial>
        <mass>1.0</mass>
        <inertia>
          <ixx>0.166666666666667</ixx>
          <ixy>0</ixy>
          <ixz>0</ixz>
          <iyy>0.166666666666667</iyy>
          <iyz>0</iyz>
          <izz>0.166666666666667</izz>
        </inertia>
      </inertial>
      <visual name="visual">
        <geometry>
          <box>
            <size>0.2 0.02 0.1</size>
          </box>
        </geometry>
        <material>
          <diffuse>1 0 0 1</diffuse>
        </material>
      </visual>
      <collision name="collision_left">
        <geometry>
          <box>
            <size>0.2 0.02 0.1</size>
          </box>
        </geometry>
        <surface>
          <friction>
            <ode>
              <mu>1.0</mu>
              <mu2>1.0</mu2>
            </ode>
          </friction>
        </surface>
      </collision>
    </link>

      <!-- The model for a solid box of uniform density. -->
    <link name="right_finger">
      <pose>0 0.01 0 0 0 0</pose>
      <inertial>
        <mass>1.0</mass>
        <inertia>
          <ixx>0.166666666666667</ixx>
          <ixy>0</ixy>
          <ixz>0</ixz>
          <iyy>0.166666666666667</iyy>
          <iyz>0</iyz>
          <izz>0.166666666666667</izz>
        </inertia>
      </inertial>
      <visual name="visual">
        <geometry>
          <box>
            <size>0.2 0.02 0.1</size>
          </box>
        </geometry>
        <material>
          <diffuse>1 0 0 1</diffuse>
        </material>
      </visual>
      <collision name="collision_right">
        <geometry>
          <box>
            <size>0.2 0.02 0.1</size>
          </box>
        </geometry>
        <surface>
          <friction>
            <ode>
              <mu>1.0</mu>
              <mu2>1.0</mu2>
            </ode>
          </friction>
        </surface>
      </collision>
    </link>
  </model>
</sdf>