<?xml version="1.0"?>
<sdf version="1.7">
  <model name="gripper">
    <link name="gripper_body">
      <pose>0 0 0 0 0 0</pose>
      <inertial>
        <mass>1</mass>
        <inertia>
          <ixx>0.1</ixx>
          <ixy>0</ixy>
          <ixz>0</ixz>
          <iyy>0.1</iyy>
          <iyz>0</iyz>
          <izz>0.1</izz>
        </inertia>
      </inertial>
      <visual name="visual">
        <pose>0 0 0.1 0 0 0</pose>
        <geometry>
          <box>
            <size>0.05 0.15 0.1</size>
          </box>
        </geometry>
        <material>
          <diffuse>0 0 1 1</diffuse>
        </material>
      </visual>      
    </link>

    <joint name="y_slider_left" type="prismatic">
      <parent>gripper_body</parent>
      <child>left_finger</child>
      <axis>
        <xyz>0 1 0</xyz>
      </axis>
    </joint>

    <joint name="y_slider_right" type="prismatic">
      <parent>gripper_body</parent>
      <child>right_finger</child>
      <axis>
        <xyz>0 1 0</xyz>
      </axis>
    </joint>
    
    <link name="ghost_body_y">
      <inertial>
        <mass>1.0e-6</mass>
        <inertia>
          <ixx>1.0e-6</ixx>
          <ixy>0</ixy>
          <ixz>0</ixz>
          <iyy>1.0e-6</iyy>
          <iyz>0</iyz>
          <izz>1.0e-6</izz>
        </inertia>
      </inertial>
    </link>

    <link name="ghost_body_z">
      <inertial>
        <mass>1.0e-6</mass>
        <inertia>
          <ixx>1.0e-6</ixx>
          <ixy>0</ixy>
          <ixz>0</ixz>
          <iyy>1.0e-6</iyy>
          <iyz>0</iyz>
          <izz>1.0e-6</izz>
        </inertia>
      </inertial>
    </link>

    <joint name="y_slider" type="prismatic">
      <parent>world</parent>
      <child>ghost_body_y</child>
      <axis>
        <xyz>0 1 0</xyz>
        <!-- Drake attaches an actuator to all joints with a non-zero effort
             limit. We do not want an actuator for this joint. -->
        <limit>
          <effort>0</effort>
        </limit>
      </axis>
    </joint>

    <joint name="z_slider" type="prismatic">
      <parent>ghost_body_y</parent>
      <child>ghost_body_z</child>
      <axis>
        <xyz>0 0 1</xyz>
        <!-- Drake attaches an actuator to all joints with a non-zero effort
             limit. We do not want an actuator for this joint and therefore we
             set a zero effort limit. -->
        <limit>
          <effort>0</effort>
        </limit>
      </axis>
    </joint>

    <joint name="rotation" type="revolute">
      <parent>ghost_body_z</parent>
      <child>gripper_body</child>
      <axis>
        <xyz>1 0 0</xyz>
        <!-- Drake attaches an actuator to all joints with a non-zero effort
             limit. We do not want an actuator for this joint and therefore we
             set a zero effort limit. -->
        <limit>
          <effort>0</effort>
        </limit>
      </axis>
    </joint>


    <!-- The model for a solid box of uniform density. -->
    <link name="left_finger">
      <pose>0 -0.01 0 0 0 0</pose>
      <inertial>
        <mass>1.0</mass>
        <inertia>
          <ixx>0.166666666666667</ixx>
          <ixy>0</ixy>
          <ixz>0</ixz>
          <iyy>0.166666666666667</iyy>
          <iyz>0</iyz>
          <izz>0.166666666666667</izz>
        </inertia>
      </inertial>
      <visual name="visual">
        <geometry>
          <box>
            <size>0.05 0.02 0.1</size>
          </box>
        </geometry>
        <material>
          <diffuse>1 0 0 1</diffuse>
        </material>
      </visual>
      <collision name="collision_left">
        <geometry>
          <box>
            <size>0.05 0.02 0.1</size>
          </box>
        </geometry>
        <surface>
          <friction>
            <ode>
              <mu>1.0</mu>
              <mu2>1.0</mu2>
            </ode>
          </friction>
        </surface>
      </collision>
    </link>

      <!-- The model for a solid box of uniform density. -->
    <link name="right_finger">
      <pose>0 0.01 0 0 0 0</pose>
      <inertial>
        <mass>1.0</mass>
        <inertia>
          <ixx>0.166666666666667</ixx>
          <ixy>0</ixy>
          <ixz>0</ixz>
          <iyy>0.166666666666667</iyy>
          <iyz>0</iyz>
          <izz>0.166666666666667</izz>
        </inertia>
      </inertial>
      <visual name="visual">
        <geometry>
          <box>
            <size>0.05 0.02 0.1</size>
          </box>
        </geometry>
        <material>
          <diffuse>1 0 0 1</diffuse>
        </material>
      </visual>
      <collision name="collision_right">
        <geometry>
          <box>
            <size>0.05 0.02 0.1</size>
          </box>
        </geometry>
        <surface>
          <friction>
            <ode>
              <mu>1.0</mu>
              <mu2>1.0</mu2>
            </ode>
          </friction>
        </surface>
      </collision>
    </link>
  </model>
</sdf>