# This sdf file is auto-generated.
# Manual modification is not recommended.
<sdf version='1.6'>
  <model name='plate'>


    <!-- Ghost body of negligible mass. -->
    <link name="ghost_body_y">
      <inertial>
        <mass>1.0e-6</mass>
        <inertia>
          <ixx>1.0e-6</ixx>
          <ixy>0</ixy>
          <ixz>0</ixz>
          <iyy>1.0e-6</iyy>
          <iyz>0</iyz>
          <izz>1.0e-6</izz>
        </inertia>
      </inertial>
    </link>

    <link name="ghost_body_z">
      <inertial>
        <mass>1.0e-6</mass>
        <inertia>
          <ixx>1.0e-6</ixx>
          <ixy>0</ixy>
          <ixz>0</ixz>
          <iyy>1.0e-6</iyy>
          <iyz>0</iyz>
          <izz>1.0e-6</izz>
        </inertia>
      </inertial>
    </link>

    <joint name="y_slider" type="prismatic">
      <parent>world</parent>
      <child>ghost_body_y</child>
      <axis>
        <xyz>0 1 0</xyz>
        <!-- Drake attaches an actuator to all joints with a non-zero effort
             limit. We do not want an actuator for this joint. -->
        <limit>
          <effort>0</effort>
        </limit>
      </axis>
    </joint>

    <joint name="z_slider" type="prismatic">
      <parent>ghost_body_y</parent>
      <child>ghost_body_z</child>
      <axis>
        <xyz>0 0 1</xyz>
        <!-- Drake attaches an actuator to all joints with a non-zero effort
             limit. We do not want an actuator for this joint and therefore we
             set a zero effort limit. -->
        <limit>
          <effort>0</effort>
        </limit>
      </axis>
    </joint>

    <joint name="rotation" type="revolute">
      <parent>ghost_body_z</parent>
      <child>plate_body</child>
      <axis>
        <xyz>1 0 0</xyz>
        <!-- Drake attaches an actuator to all joints with a non-zero effort
             limit. We do not want an actuator for this joint and therefore we
             set a zero effort limit. -->
        <limit>
          <effort>0</effort>
        </limit>
      </axis>
    </joint>
  <link name='plate_body'>
  <pose> 0 0 0 0 0 0 </pose>
  <inertial>
     <mass> 0.010000 </mass>
     <inertia>
       <ixx>0.000100</ixx>
       <iyy>0.000100</iyy>
       <izz>0.000100</izz>
       <ixy>0.000000</ixy>
       <iyz>0.000000</iyz>
       <ixz>0.000000</ixz>
     </inertia>
  </inertial>

  <visual name='visual_000'>
  <pose> 0 0.000000 0.000000 0 0 0 </pose>
  <geometry>
    <sphere>
       <radius>0.025000</radius>
    </sphere>
  </geometry>
  <material>
    <diffuse>1.0 1.0 1.0 1.0</diffuse>
  </material>
  </visual>

  <collision name='collision_000'>
  <pose> 0 0.000000 0.000000 0 0 0 </pose>
  <geometry>
    <sphere>
       <radius>0.025000</radius>
    </sphere>
  </geometry>
  <surface>
    <friction>
      <ode>
        <mu>0.800000</mu>
        <mu2>0.800000</mu2>
      </ode>
    </friction>
  </surface>
  </collision>
  <visual name='visual_001'>
  <pose> 0 -0.050000 0.000000 0 0 0 </pose>
  <geometry>
    <sphere>
       <radius>0.025000</radius>
    </sphere>
  </geometry>
  <material>
    <diffuse>1.0 1.0 1.0 1.0</diffuse>
  </material>
  </visual>

  <collision name='collision_001'>
  <pose> 0 -0.050000 0.000000 0 0 0 </pose>
  <geometry>
    <sphere>
       <radius>0.025000</radius>
    </sphere>
  </geometry>
  <surface>
    <friction>
      <ode>
        <mu>0.800000</mu>
        <mu2>0.800000</mu2>
      </ode>
    </friction>
  </surface>
  </collision>
  <visual name='visual_002'>
  <pose> 0 0.050000 0.000000 0 0 0 </pose>
  <geometry>
    <sphere>
       <radius>0.025000</radius>
    </sphere>
  </geometry>
  <material>
    <diffuse>1.0 1.0 1.0 1.0</diffuse>
  </material>
  </visual>

  <collision name='collision_002'>
  <pose> 0 0.050000 0.000000 0 0 0 </pose>
  <geometry>
    <sphere>
       <radius>0.025000</radius>
    </sphere>
  </geometry>
  <surface>
    <friction>
      <ode>
        <mu>0.800000</mu>
        <mu2>0.800000</mu2>
      </ode>
    </friction>
  </surface>
  </collision>
  <visual name='visual_003'>
  <pose> 0 -0.090000 0.008000 0 0 0 </pose>
  <geometry>
    <sphere>
       <radius>0.020000</radius>
    </sphere>
  </geometry>
  <material>
    <diffuse>1.0 1.0 1.0 1.0</diffuse>
  </material>
  </visual>

  <collision name='collision_003'>
  <pose> 0 -0.090000 0.008000 0 0 0 </pose>
  <geometry>
    <sphere>
       <radius>0.020000</radius>
    </sphere>
  </geometry>
  <surface>
    <friction>
      <ode>
        <mu>0.800000</mu>
        <mu2>0.800000</mu2>
      </ode>
    </friction>
  </surface>
  </collision>
  <visual name='visual_004'>
  <pose> 0 0.090000 0.008000 0 0 0 </pose>
  <geometry>
    <sphere>
       <radius>0.020000</radius>
    </sphere>
  </geometry>
  <material>
    <diffuse>1.0 1.0 1.0 1.0</diffuse>
  </material>
  </visual>

  <collision name='collision_004'>
  <pose> 0 0.090000 0.008000 0 0 0 </pose>
  <geometry>
    <sphere>
       <radius>0.020000</radius>
    </sphere>
  </geometry>
  <surface>
    <friction>
      <ode>
        <mu>0.800000</mu>
        <mu2>0.800000</mu2>
      </ode>
    </friction>
  </surface>
  </collision>
  <visual name='visual_005'>
  <pose> 0 0.125000 0.011000 0 0 0 </pose>
  <geometry>
    <sphere>
       <radius>0.015000</radius>
    </sphere>
  </geometry>
  <material>
    <diffuse>1.0 1.0 1.0 1.0</diffuse>
  </material>
  </visual>

  <collision name='collision_005'>
  <pose> 0 0.125000 0.011000 0 0 0 </pose>
  <geometry>
    <sphere>
       <radius>0.015000</radius>
    </sphere>
  </geometry>
  <surface>
    <friction>
      <ode>
        <mu>0.800000</mu>
        <mu2>0.800000</mu2>
      </ode>
    </friction>
  </surface>
  </collision>
  <visual name='visual_006'>
  <pose> 0 -0.125000 0.011000 0 0 0 </pose>
  <geometry>
    <sphere>
       <radius>0.015000</radius>
    </sphere>
  </geometry>
  <material>
    <diffuse>1.0 1.0 1.0 1.0</diffuse>
  </material>
  </visual>

  <collision name='collision_006'>
  <pose> 0 -0.125000 0.011000 0 0 0 </pose>
  <geometry>
    <sphere>
       <radius>0.015000</radius>
    </sphere>
  </geometry>
  <surface>
    <friction>
      <ode>
        <mu>0.800000</mu>
        <mu2>0.800000</mu2>
      </ode>
    </friction>
  </surface>
  </collision>
  <visual name='visual_007'>
  <pose> 0 0.150000 0.017000 0 0 0 </pose>
  <geometry>
    <sphere>
       <radius>0.010000</radius>
    </sphere>
  </geometry>
  <material>
    <diffuse>1.0 1.0 1.0 1.0</diffuse>
  </material>
  </visual>

  <collision name='collision_007'>
  <pose> 0 0.150000 0.017000 0 0 0 </pose>
  <geometry>
    <sphere>
       <radius>0.010000</radius>
    </sphere>
  </geometry>
  <surface>
    <friction>
      <ode>
        <mu>0.800000</mu>
        <mu2>0.800000</mu2>
      </ode>
    </friction>
  </surface>
  </collision>
  <visual name='visual_008'>
  <pose> 0 -0.150000 0.017000 0 0 0 </pose>
  <geometry>
    <sphere>
       <radius>0.010000</radius>
    </sphere>
  </geometry>
  <material>
    <diffuse>1.0 1.0 1.0 1.0</diffuse>
  </material>
  </visual>

  <collision name='collision_008'>
  <pose> 0 -0.150000 0.017000 0 0 0 </pose>
  <geometry>
    <sphere>
       <radius>0.010000</radius>
    </sphere>
  </geometry>
  <surface>
    <friction>
      <ode>
        <mu>0.800000</mu>
        <mu2>0.800000</mu2>
      </ode>
    </friction>
  </surface>
  </collision>
  </link>

  </model>
</sdf>
