<sdf version='1.6'>
  <model name='three_link_arm'>

  <link name="link_0">
  <pose> 0 0 0 0 0 0</pose>
  <visual name='ball'>
    <pose frame=''> 0 0 0 0 0 0 </pose>
    <geometry>
      <sphere>
       <radius>0.05</radius>
      </sphere>
    </geometry>
  </visual>
  </link>

  <!-- joint between link_0 and link_1 -->
  <joint name="joint_1" type="revolute">
    <child>link_1</child>
    <parent>link_0</parent>
    <pose> 0 -0.5 0 0 0 0 </pose>
    <axis>
      <xyz> 1 0 0 </xyz>
    </axis>
  </joint>

  <link name="link_1">
  <pose> 0 0.5 0 0 0 0</pose>
  <inertial>
      <mass>1</mass>
      <inertia>
        <ixx>0.0833</ixx>
        <ixy>0</ixy>
        <ixz>0</ixz>
        <iyy>0</iyy>
        <iyz>0</iyz>
        <izz>0.0833</izz>
      </inertia>
  </inertial>

  <visual name='cylinder'>
    <pose> 0 0.0 0 1.5708 0 0</pose>
    <geometry>
      <cylinder>
        <length>0.9</length>
        <radius>0.05</radius>
      </cylinder>
    </geometry>
  </visual>

  <visual name='ball'>
    <pose>0 0.5 0 0 0 0</pose>
    <geometry>
      <sphere>
       <radius>0.05</radius>
      </sphere>
    </geometry>
  </visual>
  </link>

  <!-- joint between link_1 and link_2 -->
  <joint name="joint_2" type="revolute">
    <child>link_2</child>
    <parent>link_1</parent>
    <pose frame=""> 0 -0.5 0 0 0 0</pose>
    <axis>
      <xyz> 1 0 0 </xyz>
    </axis>
  </joint>

  <link name="link_2">
  <pose> 0 1.5 0 0 0 0</pose>
  <inertial>
      <mass>1</mass>
      <inertia>
        <ixx>0.0833</ixx>
        <ixy>0</ixy>
        <ixz>0</ixz>
        <iyy>0</iyy>
        <iyz>0</iyz>
        <izz>0.0833</izz>
      </inertia>
  </inertial>

  <visual name='cylinder'>
    <pose> 0 0.0 0 1.5708 0 0</pose>
    <geometry>
      <cylinder>
        <length>0.9</length>
        <radius>0.05</radius>
      </cylinder>
    </geometry>
  </visual>

  <visual name='ball'>
    <pose frame=''>0 0.5 0 0 0 0</pose>
    <geometry>
      <sphere>
       <radius>0.05</radius>
      </sphere>
    </geometry>
  </visual>
  </link>

  <!-- joint between link_3 and link_2 -->
  <joint name="joint_3" type="revolute">
    <child>link_3</child>
    <parent>link_2</parent>
    <pose> 0 -0.5 0 0 0 0 </pose>
    <axis>
      <xyz> 1 0 0 </xyz>
    </axis>
  </joint>

  <link name="link_3">
    <pose> 0 2.5 0 0 0 0</pose>
    <inertial>
      <mass>1</mass>
      <inertia>
          <ixx>0.0833</ixx>
          <ixy>0</ixy>
          <ixz>0</ixz>
          <iyy>0</iyy>
          <iyz>0</iyz>
          <izz>0.0833</izz>
      </inertia>
    </inertial>

    <visual name='cylinder'>
      <pose> 0 0 0 1.5708 0 0</pose>
      <geometry>
        <cylinder>
          <length>0.9</length>
          <radius>0.05</radius>
        </cylinder>
      </geometry>
    </visual>

  </link>

  <!-- joint between link_3 and link_ee -->
  <joint name="joint_ee" type='fixed'>
    <child>link_ee</child>
    <parent>link_3</parent>
    <pose> 0 0.0 0 0 0 0 </pose>
  </joint>

  <link name="link_ee">
    <pose> 0 3.0 0 0 0 0</pose>

    <visual name='ball'>
      <pose>0 0.0 0 0 0 0</pose>
      <geometry>
        <sphere>
         <radius>0.1</radius>
        </sphere>
      </geometry>
    </visual>

    <collision name='collision_ee'>
      <pose>0 0.0 0 0 0 0</pose>
      <geometry>
        <sphere>
         <radius>0.1</radius>
        </sphere>
      </geometry>
    </collision>
  </link>

  </model>
</sdf>
