<sdf version='1.6'>
  <model name='robot_left'>

  <link name="link_0">
  <pose> 0 0 0 0 0 0</pose>
  <inertial>
    <mass>1</mass>
    <inertia>
      <ixx>0.0033</ixx>
      <ixy>0</ixy>
      <ixz>0</ixz>
      <iyy>0.0033</iyy>
      <iyz>0</iyz>
      <izz>0.0033</izz>
    </inertia>
  </inertial>

  <visual name='ball'>
    <pose frame=''> 0 0 0 0 0 0 </pose>
    <geometry>
      <sphere>
       <radius>0.05</radius>
      </sphere>
    </geometry>
  </visual>

  <collision name="collision">
    <pose frame=''> 0 0 0 0 0 0 </pose>
    <geometry>
      <sphere>
        <radius>0.05</radius>
      </sphere>
    </geometry>
    <surface>
      <friction>
        <ode>
          <mu>0.8</mu>
          <mu2>0.8</mu2>
        </ode>
      </friction>
    </surface>
  </collision>
  </link>

  <joint name="joint_1" type="revolute">
    <child>link_1</child>
    <parent>link_0</parent>
    <axis>
      <xyz expressed_in="__model__"> 1 0 0 </xyz>
      <limit>
        <lower>-1.5708</lower>
        <upper>0</upper>
        <effort>300</effort>  
      </limit>
    </axis>
  </joint>

  <link name="link_1">
  <pose> 0 0 0 0 0 0</pose>
  <inertial>
      <mass>1</mass>
      <inertia>
        <ixx>0.0033</ixx>
        <ixy>0</ixy>
        <ixz>0</ixz>
        <iyy>0.0033</iyy>
        <iyz>0</iyz>
        <izz>0.0033</izz>
      </inertia>
  </inertial>

  <visual name='ball0'>
    <pose> 0 -0.1 0 0 0 0</pose>
    <geometry>
      <sphere>
        <radius>0.05</radius>
      </sphere>
    </geometry>
    <material>
      <diffuse>0.2 0.2 0.2 0.8</diffuse>
    </material>
  </visual>

  <visual name='ball1'>
    <pose>0 -0.2 0 0 0 0</pose>
    <geometry>
      <sphere>
       <radius>0.05</radius>
      </sphere>
    </geometry>
    <material>
      <diffuse>0.2 0.2 0.2 0.8</diffuse>    
    </material>
  </visual>

  <visual name='ball2'>
    <pose>0 -0.3 0 0 0 0</pose>
    <geometry>
      <sphere>
       <radius>0.05</radius>
      </sphere>
    </geometry>
    <material>
      <diffuse>0.8 0.8 0.8 0.8</diffuse>
    </material>
  </visual>

  <visual name='cylinder'>
    <pose>0 -0.15 0 1.57079632 0 0</pose>
    <geometry>
      <cylinder>
       <radius>0.05</radius>
       <length>0.1</length>
      </cylinder>
    </geometry>
    <material>
      <diffuse>0.2 0.2 0.2 1.0</diffuse>
    </material>
  </visual>


  <collision name="collision_0">
    <pose frame=''> 0 -0.1 0 0 0 0 </pose>
    <geometry>
      <sphere>
        <radius>0.05</radius>
      </sphere>
    </geometry>
    <surface>
      <friction>
        <ode>
          <mu>0.8</mu>
          <mu2>0.8</mu2>
        </ode>
      </friction>
    </surface>
  </collision>

  <collision name="collision_1">
    <pose frame=''> 0 -0.2 0 0 0 0 </pose>
    <geometry>
      <sphere>
        <radius>0.05</radius>
      </sphere>
    </geometry>
    <surface>
      <friction>
        <ode>
          <mu>0.8</mu>
          <mu2>0.8</mu2>
        </ode>
      </friction>
    </surface>
  </collision>

  <collision name="collision_2">
    <pose frame=''> 0 -0.3 0 0 0 0 </pose>
    <geometry>
      <sphere>
        <radius>0.05</radius>
      </sphere>
    </geometry>
    <surface>
      <friction>
        <ode>
          <mu>0.8</mu>
          <mu2>0.8</mu2>
        </ode>
      </friction>
    </surface>
  </collision>
  </link>

  <joint name="joint_2" type="revolute">
    <child>link_2</child>
    <parent>link_1</parent>
    <axis>
      <xyz> 1 0 0 </xyz>
      <limit>
        <lower>-2.4</lower>
        <upper>0</upper>
      </limit>
    </axis>
  </joint>

  <link name="link_2">
  <pose> 0 -0.3 0 0 0 0</pose>
  <inertial>
      <mass>1</mass>
      <inertia>
        <ixx>0.0033</ixx>
        <ixy>0</ixy>
        <ixz>0</ixz>
        <iyy>0.0033</iyy>
        <iyz>0</iyz>
        <izz>0.0033</izz>
      </inertia>
  </inertial>

  <visual name='ball0'>
    <pose> 0 -0.1 0 0 0 0</pose>
    <geometry>
      <sphere>
        <radius>0.05</radius>
      </sphere>
    </geometry>
    <material>
      <diffuse>0.2 0.2 0.2 0.8</diffuse>
    </material>
  </visual>

  <visual name='ball1'>
    <pose>0 -0.2 0 0 0 0</pose>
    <geometry>
      <sphere>
       <radius>0.05</radius>
      </sphere>
    </geometry>
    <material>
      <diffuse>0.2 0.2 0.2 0.8</diffuse>
    </material>
  </visual>

  <visual name='cylinder'>
    <pose>0 -0.15 0 1.57079632 0 0</pose>
    <geometry>
      <cylinder>
       <radius>0.05</radius>
       <length>0.1</length>
      </cylinder>
    </geometry>
    <material>
      <diffuse>0.2 0.2 0.2 1.0</diffuse>
    </material>
  </visual>

  <collision name="collision_0">
    <pose frame=''> 0 -0.1 0 0 0 0 </pose>
    <geometry>
      <sphere>
        <radius>0.05</radius>
      </sphere>
    </geometry>
    <surface>
      <friction>
        <ode>
          <mu>0.8</mu>
          <mu2>0.8</mu2>
        </ode>
      </friction>
    </surface>
  </collision>

  <collision name="collision_1">
    <pose frame=''> 0 -0.2 0 0 0 0 </pose>
    <geometry>
      <sphere>
        <radius>0.05</radius>
      </sphere>
    </geometry>
    <surface>
      <friction>
        <ode>
          <mu>0.8</mu>
          <mu2>0.8</mu2>
        </ode>
      </friction>
    </surface>
  </collision> 
  </link>
  </model>
</sdf>



